Workbook

Sheet Premissas
A1: Premissas
A2: Substitua os valores em azul. Fundo amarelo = premissa critica ou celula aguardando o seu numero. Fundo verde-claro = total calculado.
A4: Parametro | B4: Valor | C4: Unidade | D4: Nota
A6: 1. BASE DE PONTOS NO ESCOPO
A7: Ano-base (Ano 1) | B7: 2026 | C7: ano | D7: Todas as projecoes partem daqui
A8: Pontos de pivo (Nexus + SmartConnect combinados) | B8: 3800 | C8: pontos | D8: Informado por William em 02/set/2026. Banco de dados (Notion, BILLING BUSINESS MODEL, ago/2026) registra 3.847 — reconciliar quando o corte de dados coincidir.
A9: Anuidade do ponto de pivo | B9: 1200 | C9: R$/ponto/ano | D9: Preco de tabela Brasil (proposta Helton, 2024). Sem desconto de volume.
A10: Pontos de Irripump | B10: 803 | C10: pontos | D10: Informado por William em 02/set/2026 (confere com Notion, ago/2026).
A11: Anuidade do ponto de Irripump | B11: 800 | C11: R$/ponto/ano | D11: Novo no escopo — antes faturado fora desta analise.
A12: Pontos de medidor de nivel | B12: 172 | C12: pontos | D12: Informado por William em 02/set/2026 (confere com Notion, ago/2026).
A13: Anuidade do ponto de medidor de nivel | B13: 800 | C13: R$/ponto/ano | D13: Novo no escopo — antes faturado fora desta analise.
A14: Total de pontos no escopo | B14: =B8+B10+B12 | C14: pontos | D14: Pivo + Irripump + medidor de nivel — os tres produtos agora geram anuidade de plataforma.
A15: Receita teorica do ano-base (total) | B15: =B8*B9+B10*B11+B12*B13 | C15: R$ | D15: Soma dos tres produtos, ao preco de tabela cheio.
A16: Receita efetivamente recebida no ano-base (referencia real) | B16: 1841996 | C16: R$ | D16: Stripe charge jan-ago/2026 = R$1.227.997, anualizado (÷8×12). Fonte: Notion, BILLING BUSINESS MODEL, 01/set/2026. Substitua pelo fechado do ano quando tiver.
A17: Novos entrantes por ano (pontos, total combinado) | B17: 250 | C17: pontos/ano | D17: Pontos novos vendidos a cada ano, nos tres produtos.
A18: Crescimento dos novos entrantes | B18: 0 | C18: % a.a. | D18: Zero mantem o mesmo volume de entrantes ao longo do horizonte.
A19: Churn anual da base | B19: 0.03 | C19: % a.a. | D19: Pontos que saem da plataforma.
A20: Reajuste anual de preco | B20: 0.05 | C20: % a.a. | D20: Indice contratual, aplicado a anuidade de todos os produtos.
A22: 2. DESCONTOS E COBRANCA
A23: Duas tabelas de referencia global (imagem enviada por William, 02/set/2026 — mesmos dados da Notion BILLING BUSINESS MODEL) e as premissas de desconto praticadas hoje no Brasil.
A25: Tabela global — desconto por volume x prazo, sobre o preco cheio do ano 1 (referencia)
A26: Faixa de dispositivos | B26: 1 ano | C26: 2 anos | D26: 3 anos
A27: 1 - 10 | B27: 0 | C27: 0.11 | D27: 0.23
A28: 11 - 20 | B28: 0.05 | C28: 0.16 | D28: 0.27
A29: 21 - 30 | B29: 0.11 | C29: 0.21 | D29: 0.31
A30: 31 - 40 | B30: 0.17 | C30: 0.26 | D30: 0.36
A31: 41 - 50 | B31: 0.24 | C31: 0.33 | D31: 0.41
A33: Tabela global — preco total do contrato por device (USD), conforme duracao (referencia)
A34: Faixa de dispositivos | B34: 1 ano | C34: 2 anos (total) | D34: 3 anos (total)
A35: 1 - 10 | B35: 220 | C35: 390 | D35: 510
A36: 11 - 20 | B36: 209 | C36: 370.5 | D36: 484.5
A37: 21 - 30 | B37: 195.8 | C37: 347.1 | D37: 453.9
A38: 31 - 40 | B38: 182.6 | C38: 323.7 | D38: 423.3
A39: 41 - 50 | B39: 167.2 | C39: 296.4 | D39: 387.6
A41: Desconto medio no pacote plurianual (Brasil, pratica atual) | B41: 0.2 | C41: % sobre o cheio | D41: Negociado caso a caso para evitar o bloqueio de 15 dias. Ver narrativa — a anuidade virou moeda de desconto.
A42: Desconto medio na anuidade avulsa | B42: 0.08 | C42: % sobre o cheio | D42: Negociacao caso a caso na renovacao.
A43: Inadimplencia | B43: 0 | C43: % da receita faturada | D43: Faturado e nao recebido.
A44: Prazo medio de recebimento | B44: 30 | C44: dias | D44: Da emissao ao caixa.
A45: Anos cobertos pelo pacote | B45: 3 | C45: anos | D45: Pagamento no ano t cobre t ate t+n-1.
A47: NOTA PARA O ARGUMENTO "NO MUNDO E DIFERENTE, NO BRASIL E DIFERENTE": a tabela global da desconto por VOLUME e por PRAZO — quem compra mais e por mais tempo paga menos. O Brasil, com ~3.800 pontos de pivo (o maior mercado da empresa) e pacotes plurianuais recorrentes, deveria estar no topo dessa curva. Em vez disso, R$1.200/ano equivale a US$211/device (cambio R$5,70), o que cai exatamente no pior tier direto da tabela — 11 a 20 dispositivos, contrato de 1 ano (US$209). Depois de cortesia e pacotes com desconto, o efetivo recebido se aproxima do nivel de DEALER global (US$104). A logica que sustentaria tratar o Brasil diferente aponta para o sentido oposto do que se pratica hoje. Desenvolvimento completo do argumento: ver Narrativa e Roteiro de Perguntas (documentos separados).
...

Sheet Base de Pontos
A1: Base de pontos
A2: A anuidade e cobrada por equipamento Irricontrol. Pivo, Irripump e medidor de nivel agora entram todos no escopo desta analise.
A4: PONTOS NO ESCOPO DA ANALISE
A5: Produto | B5: Aplicacao | C5: Pontos | D5: Anuidade | E5: Receita teorica | F5: % da base | G5: Observacao
A6: Pivo (Nexus + SmartConnect) | B6: Pivo retrofitado e pivo novo | C6: =Premissas!$B$8 | D6: =Premissas!$B$9 | E6: =C6*D6 | F6: =C6/$C$9 | G6: Painel instalado em pivo existente ou pivo novo ja conectado de fabrica
A7: Irripump | B7: Bombeamento e transposicao | C7: =Premissas!$B$10 | D7: =Premissas!$B$11 | E7: =C7*D7 | F7: =C7/$C$9 | G7: Gestao de captacao e recalque — agora dentro do escopo de anuidade
A8: Medidor de nivel | B8: Poco e reservatorio | C8: =Premissas!$B$12 | D8: =Premissas!$B$13 | E8: =C8*D8 | F8: =C8/$C$9 | G8: Medicao de nivel em tempo real — agora dentro do escopo de anuidade
A9: Total no escopo | C9: =SUM(C6:C8) | E9: =SUM(E6:E8) | F9: =C9/$C$9 | G9: Todos os produtos com anuidade agora somam este total
A11: EVOLUCAO DA BASE NO ESCOPO
A12: Indicador | B12: Valor | G12: Leitura
A13: Pontos no inicio do ano-base | B13: =C9 | G13: Base instalada de partida, nos tres produtos
A14: Novos entrantes por ano | B14: =Premissas!$B$17 | G14: Ritmo comercial assumido
A15: Churn anual | B15: =Premissas!$B$19 | G15: Pontos que saem da plataforma
A16: Crescimento liquido no primeiro ano | B16: =B14-B13*B15 | G16: Entrantes menos saidas
A17: Crescimento liquido em percentual | B17: =B16/B13 | G17: Ritmo de expansao da base
A18: Pontos ao fim do ano 1 | B18: =B13+B16 | G18: Base de saida do primeiro ano
A19: Anos para dobrar a base | B19: =IF(B17<=0,"n/a",LN(2)/LN(1+B17)) | G19: Mantido o ritmo atual de entrada e saida

Sheet Pacote vs Anuidade
A1: Pacote vs Anuidade — simulador
A2: Simule o efeito de vender pacote plurianual para a base atual e para os novos entrantes, ano a ano, e compare com o cenario em que ninguem fecha pacote. Dados ficticios — edite os campos em azul. Presume pacotes de 3 anos (padrao das Premissas); se mudar o prazo do pacote em Premissas, revise manualmente as formulas de "pontos presos" mais abaixo.
A4: PARAMETROS DO SIMULADOR
A5: Base atual (pontos faturaveis hoje) | B5: 4775 | C5: pontos | D5: Ponto de partida do simulador. Ficticio — edite livremente para testar outros tamanhos de base.
A6: Anuidade cheia do ano 0 (R$/ponto) | B6: =Premissas!$B$15/Premissas!$B$14 | C6: R$/ponto/ano | D6: Media ponderada dos tres produtos, vinda das Premissas.
A7: Desconto do pacote (% sobre o cheio) | B7: =Premissas!$B$41 | D7: Vem das Premissas — pratica atual do comercial.
A8: Anos cobertos pelo pacote | B8: =Premissas!$B$45
A9: Reajuste anual de preco | B9: =Premissas!$B$20
A10: Churn anual (sobre quem fica em anuidade) | B10: =Premissas!$B$19
A12: SIMULACAO ANO A ANO — DADOS FICTICIOS (edite em azul)
A13: Indicador | B13: Ano 0 | C13: Ano 1 | D13: Ano 2 | E13: Ano 3 | F13: Ano 4 | G13: Ano 5
A14: Novos entrantes no ano | B14: 200 | C14: 250 | D14: 250 | E14: 250 | F14: 250 | G14: 250
A15: % de pacotes fechados no ano (dos elegiveis) | B15: 1 | C15: 0 | D15: 0 | E15: 0 | F15: 0 | G15: 0
A17: PRECO DO ANO
A18: Anuidade cheia do ano | B18: =B6 | C18: =B18*(1+$B$9) | D18: =C18*(1+$B$9) | E18: =D18*(1+$B$9) | F18: =E18*(1+$B$9) | G18: =F18*(1+$B$9)
A19: Preco do pacote (total, com desconto), por ponto | B19: =B18*$B$8*(1-$B$7) | C19: =C18*$B$8*(1-$B$7) | D19: =D18*$B$8*(1-$B$7) | E19: =E18*$B$8*(1-$B$7) | F19: =F18*$B$8*(1-$B$7) | G19: =G18*$B$8*(1-$B$7)
A21: PONTOS — QUEM DECIDE A CADA ANO
A22: Total de pontos ativos no ano (cresce igual nos dois cenarios) | B22: =$B$5+B14 | C22: =B22*(1-$B$10)+C14 | D22: =C22*(1-$B$10)+D14 | E22: =D22*(1-$B$10)+E14 | F22: =E22*(1-$B$10)+F14 | G22: =F22*(1-$B$10)+G14
A23: Pontos ainda presos em pacote vigente (nao decidem este ano) | B23: 0 | C23: =B25 | D23: =B25+C25 | E23: =C25+D25 | F23: =D25+E25 | G23: =E25+F25
A24: Pontos livres para decidir este ano | B24: =B22-B23 | C24: =C22-C23 | D24: =D22-D23 | E24: =E22-E23 | F24: =F22-F23 | G24: =G22-G23
A25: Pontos que fecham pacote novo este ano | B25: =B24*B15 | C25: =C24*C15 | D25: =D24*D15 | E25: =E24*E15 | F25: =F24*F15 | G25: =G24*G15
A26: Pontos que renovam em anuidade este ano | B26: =B24-B25 | C26: =C24-C25 | D26: =D24-D25 | E26: =E24-E25 | F26: =F24-F25 | G26: =G24-G25
A28: CAIXA — CENARIO COM PACOTE (pratica mista, conforme % informado)
A29: Caixa do ano — com pacote | B29: =B25*B19+B26*B18 | C29: =C25*C19+C26*C18 | D29: =D25*D19+D26*D18 | E29: =E25*E19+E26*E18 | F29: =F25*F19+F26*F18 | G29: =G25*G19+G26*G18
A31: CAIXA — CENARIO SEM PACOTE (contrafactual: ninguem fecha pacote)
A32: Caixa do ano — sem pacote | B32: =B22*B18 | C32: =C22*C18 | D32: =D22*D18 | E32: =E22*E18 | F32: =F22*F18 | G32: =G22*G18
A34: COMPARATIVO
A35: Diferenca do ano (com pacote menos sem pacote) | B35: =B29-B32 | C35: =C29-C32 | D35: =D29-D32 | E35: =E29-E32 | F35: =F29-F32 | G35: =G29-G32
A36: Diferenca acumulada ate o ano | B36: =B35 | C36: =B36+C35 | D36: =C36+D35 | E36: =D36+E35 | F36: =E36+F35 | G36: =F36+G35
A38: ="No ano 0, com "&TEXT(B15,"0%")&" da base e dos novos entrantes fechando pacote, o caixa daquele ano fica "&IF(B35>=0,"R$ "&TEXT(B35,"#,##0")&" ACIMA","R$ "&TEXT(ABS(B35),"#,##0")&" ABAIXO")&" do que seria vender só anuidade cheia para o mesmo grupo. Olhando o acumulado até o Ano 5, a diferença total é "&IF(G36>=0,"um GANHO de R$ ","uma PERDA de R$ ")&TEXT(ABS(G36),"#,##0")&" em relação a nunca vender pacote nenhum."

Sheet Análises
A1: Análises
A2: Projecao num unico cenario de anuidade, a partir das Premissas atuais (pacote plurianual fica no simulador "Pacote vs Anuidade"). Combina a base real conhecida com a base ilustrativa do modelo — ajuste as Premissas conforme os dados abertos forem sendo levantados.
A4: 1. CAPTURA DE PRECO — ANCORAGEM COM DADOS REAIS (Stripe, 2025)
A5: Fonte: Notion, BILLING BUSINESS MODEL / Narrativa da Tese, 01/set/2026 — nao editavel, e o registro historico real.
A6: Pivos centrais ativos (ago/2026, banco de dados real) | B6: 3847
A7: Potencial teorico anual (pivos reais x R$1.200) | B7: =B6*1200
A8: Coletado real — 2025 (Stripe charge, ano completo) | B8: 2010247
A9: Gap anual (potencial menos coletado) | B9: =B7-B8
A10: Taxa de realizacao | B10: =B8/B7
A11: O gap tem tres causas, nao uma: (1) bonificacao/cortesia intencional, (2) pacotes multi-anuais pre-pagos que aparecem como "gap" mas sao clientes ativos e em dia, e (3) inadimplencia real — o residuo depois de separar as duas primeiras. O split ainda nao foi levantado com o comercial (ver secao 3 desta aba e o roteiro de perguntas).
A15: 2. PROJECAO — CENARIO ANUIDADE (a partir das Premissas)
A16: Indicador | B16: Ano 0 | C16: Ano 1 | D16: Ano 2 | E16: Ano 3 | F16: Ano 4 | G16: Ano 5
A17: Pontos ativos no ano (Premissas: base + entrantes - churn) | B17: =Premissas!$B$14 | C17: =B17*(1-Premissas!$B$19)+Premissas!$B$17*(1+Premissas!$B$18)^1 | D17: =C17*(1-Premissas!$B$19)+Premissas!$B$17*(1+Premissas!$B$18)^2 | E17: =D17*(1-Premissas!$B$19)+Premissas!$B$17*(1+Premissas!$B$18)^3 | F17: =E17*(1-Premissas!$B$19)+Premissas!$B$17*(1+Premissas!$B$18)^4 | G17: =F17*(1-Premissas!$B$19)+Premissas!$B$17*(1+Premissas!$B$18)^5
A18: Anuidade media do ano (blended, com reajuste) | B18: =Premissas!$B$15/Premissas!$B$14 | C18: =B18*(1+Premissas!$B$20) | D18: =C18*(1+Premissas!$B$20) | E18: =D18*(1+Premissas!$B$20) | F18: =E18*(1+Premissas!$B$20) | G18: =F18*(1+Premissas!$B$20)
A19: Receita bruta | B19: =B17*B18 | C19: =C17*C18 | D19: =D17*D18 | E19: =E17*E18 | F19: =F17*F18 | G19: =G17*G18
A20: (-) Desconto comercial (anuidade avulsa) | B20: =-B19*Premissas!$B$42 | C20: =-C19*Premissas!$B$42 | D20: =-D19*Premissas!$B$42 | E20: =-E19*Premissas!$B$42 | F20: =-F19*Premissas!$B$42 | G20: =-G19*Premissas!$B$42
A21: (-) Inadimplencia | B21: =-(B19+B20)*Premissas!$B$43 | C21: =-(C19+C20)*Premissas!$B$43 | D21: =-(D19+D20)*Premissas!$B$43 | E21: =-(E19+E20)*Premissas!$B$43 | F21: =-(F19+F20)*Premissas!$B$43 | G21: =-(G19+G20)*Premissas!$B$43
A22: (-) Cortesia vigente (aproximacao, mantida constante) | B22: =-Premissas!$B$81 | C22: =$B$22 | D22: =$B$22 | E22: =$B$22 | F22: =$B$22 | G22: =$B$22
A23: (=) Receita liquida | B23: =SUM(B19:B22) | C23: =SUM(C19:C22) | D23: =SUM(D19:D22) | E23: =SUM(E19:E22) | F23: =SUM(F19:F22) | G23: =SUM(G19:G22)
A25: (-) Custo variavel (cloud, conectividade, suporte) | B25: =-B17*(Premissas!$B$54+Premissas!$B$55)*(1+Premissas!$B$57)^0 | C25: =-C17*(Premissas!$B$54+Premissas!$B$55)*(1+Premissas!$B$57)^1 | D25: =-D17*(Premissas!$B$54+Premissas!$B$55)*(1+Premissas!$B$57)^2 | E25: =-E17*(Premissas!$B$54+Premissas!$B$55)*(1+Premissas!$B$57)^3 | F25: =-F17*(Premissas!$B$54+Premissas!$B$55)*(1+Premissas!$B$57)^4 | G25: =-G17*(Premissas!$B$54+Premissas!$B$55)*(1+Premissas!$B$57)^5
A26: (-) Custo fixo da plataforma | B26: =-Premissas!$B$56*(1+Premissas!$B$57)^0 | C26: =-Premissas!$B$56*(1+Premissas!$B$57)^1 | D26: =-Premissas!$B$56*(1+Premissas!$B$57)^2 | E26: =-Premissas!$B$56*(1+Premissas!$B$57)^3 | F26: =-Premissas!$B$56*(1+Premissas!$B$57)^4 | G26: =-Premissas!$B$56*(1+Premissas!$B$57)^5
A27: (-) Custo da operacao de billing | B27: =-Premissas!$B$66*(1+Premissas!$B$57)^0 | C27: =-Premissas!$B$66*(1+Premissas!$B$57)^1 | D27: =-Premissas!$B$66*(1+Premissas!$B$57)^2 | E27: =-Premissas!$B$66*(1+Premissas!$B$57)^3 | F27: =-Premissas!$B$66*(1+Premissas!$B$57)^4 | G27: =-Premissas!$B$66*(1+Premissas!$B$57)^5
A28: (=) Custo total | B28: =SUM(B25:B27) | C28: =SUM(C25:C27) | D28: =SUM(D25:D27) | E28: =SUM(E25:E27) | F28: =SUM(F25:F27) | G28: =SUM(G25:G27)
A30: EBITDA | B30: =B23+B28 | C30: =C23+C28 | D30: =D23+D28 | E30: =E23+E28 | F30: =F23+F28 | G30: =G23+G28
A31: Margem EBITDA | B31: =B30/B23 | C31: =C30/C23 | D31: =D30/D23 | E31: =E30/E23 | F31: =F30/F23 | G31: =G30/G23
A32: Caixa acumulado (nominal) | B32: =B30 | C32: =B32+C30 | D32: =C32+D30 | E32: =D32+E30 | F32: =E32+F30 | G32: =F32+G30
A35: 3. DADOS PENDENTES PARA REFINAR ESTA ANALISE
A36: Lista viva — preencha conforme o levantamento com o comercial avancar (ver roteiro de perguntas).
A37: ☐ Split cortesia vs pagando — de que fatia da base realmente nao gera charge | B37: aguardando
A38: ☐ Breakdown do gap R$2,61M/ano — parcelas futuras de pacote / cortesia / inadimplencia real | B38: aguardando
A39: ☐ Custo operacional real do comercial (headcount, infra, CAC) | B39: aguardando
A40: ☐ Volume de receita pass-through (SAF e parceiros) dentro do charge_volume do Stripe | B40: aguardando
A41: ☐ Clientes internacionais ativos hoje — volume e receita, canal direto vs dealer | B41: aguardando
A42: ☐ ARPU por fazenda (nao por ponto/device) | B42: aguardando
A43: ☐ Distribuicao de tamanho — fazendas com 1 pivo vs 5+ vs 10+ | B43: aguardando
A44: ☐ Taxa de churn real por cohort de renovacao (nao estimada) | B44: aguardando

Sheet Migração (futuro)
A1: Migração de plataformas (futuro)
A2: Aba estacionada — nao alimenta nenhuma outra aba do modelo. Preencha quando o projeto de migracao de plataforma tiver escopo definido com a Engenharia.
A4: Parametro | B4: Valor | C4: Unidade | D4: Nota
A6: PREMISSAS DE MIGRACAO — PREENCHER QUANDO O PROJETO TIVER ESCOPO
A7: Pontos hoje na plataforma de origem | C7: pontos | D7: Quantos pontos existem na base a ser migrada
A8: Pontos tecnicamente migraveis | C8: pontos | D8: Subconjunto do total acima que o projeto consegue alcancar
A9: Ano de inicio da migracao | C9: ano | D9: Primeiro ano em que pontos migrados comecam a faturar
A10: Migrado no 1o ano do projeto | C10: % dos migraveis
A11: Migrado no 2o ano do projeto | C11: % dos migraveis
A12: Migrado no 3o ano do projeto | C12: % dos migraveis
A13: Anuidade do ponto migrado | C13: R$/ponto/ano | D13: Deixe vazio para usar a mesma anuidade da base
A14: Desconto de entrada no 1o ano | C14: % sobre o cheio
A15: Investimento de migracao por ponto | C15: R$/ponto | D15: Hardware, gateway e visita de campo
A16: Perda no processo de migracao | C16: % dos migrados

Sheet Monitoramento
A1: Monitoramento de umidade — por ponto ou por hectare
A2: Analise separada da anuidade de plataforma. Decide o modelo de cobranca a partir do que a tecnologia custou, do que custa manter, e de quando o investimento se paga. Aba isolada, pronta para colar na planilha matriz — nao depende de outras abas.
A4: 0. PARAMETROS REPLICADOS DO MODELO PRINCIPAL
A5: Usados apenas nas formulas desta aba (ano-calendario e reajuste contratual). Se colar isto ao lado da aba Premissas do modelo principal, pode trocar por referencia cruzada.
A6: Parametro | B6: Valor | C6: Unidade | H6: Nota
A7: Ano-base (ano corrente) | B7: 2026 | C7: ano | H7: Replicado do Premissas do modelo principal
A8: Reajuste contratual anual | B8: 0.05 | C8: % a.a. | H8: Replicado do Premissas do modelo principal — mesmo indice usado na anuidade
A10: 1. INVESTIMENTO E CUSTO DA TECNOLOGIA
A11: Custos vindos de Project Cost and Revenue Estimation.xlsx (arquivo enviado por William). O que a fonte nao cobre fica em branco — o modelo trata como zero e o indicador correspondente pede o dado.
A12: Parametro | B12: Valor | C12: Unidade | H12: Nota
A13: Valor pago pela tecnologia | B13: 355000 | C13: R$ | H13: Aquisicao, licenca de uso ou direito de distribuicao. E o que o payback precisa devolver
A14: Ano da aquisicao | B14: 2027 | C14: ano | H14: Ano em que o desembolso ocorreu
A15: Prazo de amortizacao contabil | B15: 3 | C15: anos | H15: Usado apenas na visao contabil
A16: Amortizacao anual | B16: =IF(OR($B$13="",$B$15="",$B$15=0),0,$B$13/$B$15) | C16: R$/ano | H16: Nao entra no calculo de payback, que trabalha com caixa
A17: Custo anual de infraestrutura e licenca | B17: 147552 | C17: R$/ano | H17: Nuvem, processamento do dado, licenca recorrente ao fornecedor
A18: Custo anual de time dedicado | C18: R$/ano | H18: Agronomia, suporte tecnico e engenharia alocados ao produto
A19: Custo fixo anual total | B19: =N($B$17)+N($B$18) | C19: R$/ano | H19: O que a receita precisa cobrir antes de gerar margem
A20: Custo variavel por ponto monitorado | B20: 9.9428571 | C20: R$/ponto/ano | H20: Conectividade, calibracao e manutencao por equipamento
A21: Custo variavel por hectare monitorado | B21: 0.14204082 | C21: R$/ha/ano | H21: Se o custo escala com area em vez de equipamento
A22: Hectares por pivo (media) | B22: 70 | C22: ha/pivo | H22: Converte um modelo de cobranca no outro
A23: Inflacao de custos | B23: 0.05 | C23: % a.a. | H23: Reajuste anual do custo fixo e variavel
A25: 2. MODELO A — COBRANCA POR PONTO (PIVO)
A26: Um preco por pivo monitorado, independente da area. Simples de vender e de faturar junto com a anuidade.
A27: Indicador | B27: Unidade | C27: =$B$7+0 | D27: =$B$7+1 | E27: =$B$7+2 | F27: =$B$7+3 | G27: =$B$7+4
A28: Ano relativo | B28: n | C28: 0 | D28: 1 | E28: 2 | F28: 3 | G28: 4
A29: Preco por ponto no ano-base | B29: R$/ponto/ano | C29: 600 | H29: Preco no ano-base. Os anos seguintes recebem o reajuste contratual
A30: Preco do ano | B30: R$/ponto/ano | C30: =N($C$29)*(1+$B$8)^C28 | D30: =N($C$29)*(1+$B$8)^D28 | E30: =N($C$29)*(1+$B$8)^E28 | F30: =N($C$29)*(1+$B$8)^F28 | G30: =N($C$29)*(1+$B$8)^G28
A31: Novas adesoes no ano | B31: pontos | C31: 0 | D31: 500 | E31: 500 | F31: 500 | G31: 500
A32: Base ativa acumulada | B32: pontos | C32: =N(C31) | D32: =C32+N(D31) | E32: =D32+N(E31) | F32: =E32+N(F31) | G32: =F32+N(G31)
A33: Receita do ano | B33: R$ | C33: =C32*C30 | D33: =D32*D30 | E33: =E32*E30 | F33: =F32*F30 | G33: =G32*G30
A34: (-) Custo variavel | B34: R$ | C34: =-C32*N($B$20)*(1+$B$23)^C28 | D34: =-D32*N($B$20)*(1+$B$23)^D28 | E34: =-E32*N($B$20)*(1+$B$23)^E28 | F34: =-F32*N($B$20)*(1+$B$23)^F28 | G34: =-G32*N($B$20)*(1+$B$23)^G28
A35: (-) Custo fixo | B35: R$ | C35: =-N($B$19)*(1+$B$23)^C28 | D35: =-N($B$19)*(1+$B$23)^D28 | E35: =-N($B$19)*(1+$B$23)^E28 | F35: =-N($B$19)*(1+$B$23)^F28 | G35: =-N($B$19)*(1+$B$23)^G28
A36: (=) Resultado de caixa do ano | B36: R$ | C36: =C33+C34+C35 | D36: =D33+D34+D35 | E36: =E33+E34+E35 | F36: =F33+F34+F35 | G36: =G33+G34+G35
A37: Resultado de caixa acumulado | B37: R$ | C37: =C36 | D37: =C37+D36 | E37: =D37+E36 | F37: =E37+F36 | G37: =F37+G36
A38: Caixa acumulado apos o investimento | B38: R$ | C38: =C37-N($B$13) | D38: =D37-N($B$13) | E38: =E37-N($B$13) | F38: =F37-N($B$13) | G38: =G37-N($B$13)
A39: Resultado contabil (com amortizacao) | B39: R$ | C39: =C36-IF(C28<N($B$15),N($B$16),0) | D39: =D36-IF(D28<N($B$15),N($B$16),0) | E39: =E36-IF(E28<N($B$15),N($B$16),0) | F39: =F36-IF(F28<N($B$15),N($B$16),0) | G39: =G36-IF(G28<N($B$15),N($B$16),0)
A41: Indicador | B41: Valor | H41: Leitura
A42: Breakeven em pontos | B42: =IF(OR(N($C$29)=0,N($C$29)-N($B$20)<=0),"preencher preco e custo",N($B$19)/(N($C$29)-N($B$20))) | H42: Quantidade que paga o custo fixo anual ao preco informado
A43: Payback do investimento | B43: =IF(OR(N($B$13)=0,MAX($C$38:$G$38)<0),"nao ocorre em 5 anos",MATCH(TRUE(),INDEX($C$38:$G$38>=0,0),0)) | H43: Ano em que o caixa acumulado cobre o valor pago pela tecnologia
A44: ROI em 5 anos | B44: =IF(N($B$13)=0,"preencher o investimento",(G37-N($B$13))/N($B$13)) | H44: Retorno sobre o valor pago, depois de cinco anos de operacao
...

Sheet Mercado
A1: Mercado — onde o manejo tem mais espaco
A2: Area irrigada cruzada com a fatia sob aspersao mecanizada e com a maturidade de manejo. As notas sao editaveis.
A4: COMO O SCORE E CALCULADO
A5: Area enderecavel = area irrigada x fatia sob aspersao mecanizada. E o pedaco do pais onde pivo e monitoramento fazem sentido.
A6: Score = area enderecavel x lacuna de manejo x acessibilidade comercial, dividido por mil.
A7: Lacuna de manejo = 4 menos a nota de maturidade. Pais com manejo consolidado tem lacuna 1; pais sem cultura de manejo tem lacuna 3.
A8: Fatia sob aspersao, maturidade e acessibilidade sao estimativas editaveis. Substitua pelo que o time comercial souber de cada praca.
A10: PAISES POR AREA ENDERECAVEL E LACUNA DE MANEJO
A11: Pais | B11: Area irrigada (mil ha) | C11: Aspersao mecanizada (% da area) | D11: Area enderecavel (mil ha) | E11: Maturidade de manejo (1 baixa a 3 alta) | F11: Acessibilidade comercial (1 a 5) | G11: Lacuna | H11: Score | I11: Posicao | J11: Observacao
A12: India | B12: 71554 | C12: 0.02 | D12: =B12*C12 | E12: 1 | F12: 2 | G12: =4-E12 | H12: =D12*G12*F12/1000 | I12: =RANK(H12,$H$12:$H$34) | J12: Area gigantesca, mas irrigacao por canal e superficie. Pouco pivo
A13: China | B13: 69160 | C13: 0.06 | D13: =B13*C13 | E13: 1 | F13: 1 | G13: =4-E13 | H13: =D13*G13*F13/1000 | I13: =RANK(H13,$H$12:$H$34) | J13: Escala enorme com barreira regulatoria e necessidade de parceiro local
A14: Estados Unidos | B14: 21490 | C14: 0.55 | D14: =B14*C14 | E14: 3 | F14: 3 | G14: =4-E14 | H14: =D14*G14*F14/1000 | I14: =RANK(H14,$H$12:$H$34) | J14: Maior parque de pivos do mundo, com manejo ja consolidado
A15: Paquistao | B15: 19340 | C15: 0.01 | D15: =B15*C15 | E15: 1 | F15: 1 | G15: =4-E15 | H15: =D15*G15*F15/1000 | I15: =RANK(H15,$H$12:$H$34) | J15: Estresse hidrico severo e baixa capacidade de pagamento
A16: Indonesia | B16: 9136 | C16: 0.01 | D16: =B16*C16 | E16: 1 | F16: 2 | G16: =4-E16 | H16: =D16*G16*F16/1000 | I16: =RANK(H16,$H$12:$H$34) | J16: Arroz irrigado, quase sem pivo
A17: Ira | B17: 7972 | C17: 0.08 | D17: =B17*C17 | E17: 1 | F17: 1 | G17: =4-E17 | H17: =D17*G17*F17/1000 | I17: =RANK(H17,$H$12:$H$34) | J17: Restricao geopolitica
A18: Brasil | B18: 6903 | C18: 0.27 | D18: =B18*C18 | E18: 2 | F18: 5 | G18: =4-E18 | H18: =D18*G18*F18/1000 | I18: =RANK(H18,$H$12:$H$34) | J18: Mercado de origem. 33.846 pivos e 2,2 milhoes de ha em 2024
A19: Tailandia | B19: 6415 | C19: 0.01 | D19: =B19*C19 | E19: 1 | F19: 2 | G19: =4-E19 | H19: =D19*G19*F19/1000 | I19: =RANK(H19,$H$12:$H$34) | J19: Irrigacao de arroz predominante
A20: Mexico | B20: 6062 | C20: 0.25 | D20: =B20*C20 | E20: 2 | F20: 4 | G20: =4-E20 | H20: =D20*G20*F20/1000 | I20: =RANK(H20,$H$12:$H$34) | J20: Pivo relevante no norte, escassez hidrica crescente
A21: Turquia | B21: 5215 | C21: 0.15 | D21: =B21*C21 | E21: 1 | F21: 3 | G21: =4-E21 | H21: =D21*G21*F21/1000 | I21: =RANK(H21,$H$12:$H$34) | J21: Parque de pivo em expansao e manejo incipiente
A22: Vietna | B22: 4600 | C22: 0.01 | D22: =B22*C22 | E22: 1 | F22: 2 | G22: =4-E22 | H22: =D22*G22*F22/1000 | I22: =RANK(H22,$H$12:$H$34) | J22: Arroz e cafe, quase sem pivo
A23: Russia | B23: 4300 | C23: 0.2 | D23: =B23*C23 | E23: 1 | F23: 1 | G23: =4-E23 | H23: =D23*G23*F23/1000 | I23: =RANK(H23,$H$12:$H$34) | J23: Pivo em expansao no sul, com restricao geopolitica e cambial
... A34: Ucrania | B34: 420 | C34: 0.4 | D34: =B34*C34 | E34: 1 | F34: 2 | G34: =4-E34 | H34: =D34*G34*F34/1000 | I34: =RANK(H34,$H$12:$H$34) | J34: Area pre-guerra. Potencial de 1,8 milhao de ha e reconstrucao financiada
A35: Total | B35: =SUM(B12:B34) | D35: =SUM(D12:D34)
A37: BRASIL — AREA SOB PIVO CENTRAL, PRINCIPAIS ESTADOS (2024)
A38: Estado | B38: Area sob pivo (ha) | C38: % do total nacional | J38: Fonte
A39: Minas Gerais | B39: 636994 | C39: =B39/2200960
A40: Bahia | B40: 404444 | C40: =B40/2200960
A41: Goias | B41: 345530 | C41: =B41/2200960
A42: Sao Paulo | B42: 247389 | C42: =B42/2200960
A43: Rio Grande do Sul | B43: 205620 | C43: =B43/2200960
A44: Mato Grosso | B44: 183033 | C44: =B44/2200960
A45: Mato Grosso do Sul | B45: 64221 | C45: =B45/2200960
A46: Total nacional | B46: 2200960 | C46: =B46/2200960 | J46: ANA e Embrapa, levantamento de pivos centrais 2024
A47: Pivos centrais no Brasil | B47: 33846 | C47: equipamentos mapeados em 2024
A48: Area media por pivo | B48: =2200960/33846 | C48: hectares
A49: Crescimento de area 2022 a 2024 | B49: 0.1468 | C49: maior salto da serie desde 1985
A50: Participacao da base no parque nacional | B50: =Premissas!$B$13/33846 | C50: pontos no escopo sobre os pivos mapeados no pais

Sheet Fontes
A1: Fontes
A2: Origem de cada numero de referencia. O que e premissa interna esta marcado como tal.
A4: Numero usado no modelo | B4: Valor | C4: Fonte | D4: Endereco
A5: Pivos centrais no Brasil | B5: 33.846 equipamentos em 2024 | C5: Embrapa e ANA — Agricultura irrigada por pivos centrais no Brasil em 2024 | D5: https://www.infoteca.cnptia.embrapa.br/infoteca/handle/doc/1167756
A6: Area irrigada por pivos no Brasil | B6: 2.200.960 ha em 2024, com alta de 14,68% no bienio | C6: Embrapa e ANA — mesmo levantamento | D6: https://www.infoteca.cnptia.embrapa.br/infoteca/handle/doc/1167756
A7: Area irrigada nos Estados Unidos | B7: 53,1 milhoes de acres, equivalentes a 21,5 milhoes de ha | C7: USDA NASS — Irrigation and Water Management Survey 2023 | D7: https://data.nass.usda.gov/Newsroom/printable/2024/10-31-2024.pdf
A8: Area irrigada por pais | B8: Ranking em mil ha | C8: Compilacao FAO AQUASTAT e CIA World Factbook | D8: https://en.wikipedia.org/wiki/List_of_countries_by_irrigated_land_area
A9: Cobertura do sensor de neutrons cosmicos | B9: 5 a 10 ha ao nivel do mar, medicao continua | C9: Bauer do Brasil — pagina do produto CosmoField | D9: https://www.bauer-br.com/pt/cosmofield/
A10: Custo de IoT gerenciado | B10: US$ 0,06 a US$ 0,075 por dispositivo por mes em 10 mil dispositivos | C10: Comparativo AWS IoT Core e Azure IoT Hub | D10: https://hubble.com/community/comparisons/aws-iot-core-vs-azure-iot-hub-pricing-what-10-000-devices-actually-costs/
A11: Custo de gateway de API | B11: AWS HTTP US$ 1,00 e REST US$ 3,50 por milhao; Azure US$ 3,50; Apigee US$ 20,00 | C11: Zuplo — comparativo de precos de gateway 2026 | D11: https://zuplo.com/learning-center/api-gateway-pricing-comparison-2026
A12: Modelos de precificacao de API | B12: Oito modelos com mecanica e faixa de preco de mercado | C12: Zuplo — 8 types of API pricing models | D12: https://zuplo.com/blog/8-types-of-api-pricing-models
A13: Salario de desenvolvedor no Brasil | B13: Media de R$ 5.985 por mes em regime CLT para back-end | C13: Portal Salario | D13: https://www.salario.com.br/profissao/desenvolvedor-back-end/
A14: Irrigacao na Ucrania | B14: 420 mil ha antes da guerra, perda de cerca de 300 mil ha | C14: Banco Mundial — The Future of Irrigation in Ukraine | D14: https://documents1.worldbank.org/curated/en/099062524074575405/pdf/P18019816676490c1b4fc1484bbd031258.pdf
A15: Modernizacao da irrigacao no Iraque | B15: Programas com FAO e Ministerio de Recursos Hidricos | C15: Nacoes Unidas no Iraque | D15: https://iraq.un.org/en/310310-fao-and-ministry-water-resources-inaugurate-model-projects-enhance-irrigation-water-use
... A17: Base de dispositivos da Irricontrol (ago/2026) | B17: 3.847 pivos efetivos, 803 Irripumps, 172 medidores de nivel | C17: Notion — BILLING BUSINESS MODEL | D17: https://app.notion.com/p/3b984fc4585080f09309e2266bea0b46
A18: Base de pontos usada nas Premissas (02/set/2026) | B18: 3.800 pontos de pivo, 803 Irripump, 172 medidor de nivel | C18: Informado por William em conversa, 02/set/2026 — proximo do dado do banco acima
A19: Receita coletada — 2025 (ano completo) | B19: R$ 2.010.247 — Stripe charge volume | C19: Notion — BILLING BUSINESS MODEL / Narrativa da Tese | D19: https://app.notion.com/p/3ce84fc45850817daa6ad7806de2ebb4
A20: Receita coletada — 2026 (jan-ago, anualizada) | B20: R$ 1.227.997 no periodo, ÷8×12 = R$ 1.841.996 anualizado | C20: Notion — BILLING BUSINESS MODEL, 01/set/2026 | D20: https://app.notion.com/p/3b984fc4585080f09309e2266bea0b46
A21: Tabela global de pricing Bauer — desconto por volume x prazo e preco por device | B21: 5 tiers (1-10 a 41-50 dispositivos) x 1/2/3 anos | C21: Imagem enviada por William, 02/set/2026 — mesmos dados arquivados na Notion BILLING BUSINESS MODEL | D21: https://app.notion.com/p/3b984fc4585080f09309e2266bea0b46
A22: Salario de operacao interna de billing | B22: R$ 3.000/mes, fator de encargos 2x, 50% do tempo alocado | C22: Informado por William em conversa, 02/set/2026
A24: Premissas internas
A25: Os grupos de cortesia agora estao na aba Premissas, secao 4 (Bonificados) — por cliente e ano, substituindo o exemplo antigo por safras (5/3/2 em dez). Preencher com o levantamento real.
A26: A aba Monitoramento esta propositalmente em branco nas premissas de custo do time dedicado.
A27: As abas Monitoramento e API Comercial estao propositalmente em branco. Os benchmarks externos servem de ancora, nao de premissa.
A28: Notas de maturidade de manejo e acessibilidade comercial na aba Mercado sao avaliacao qualitativa a calibrar com o time comercial.
